<?xml version="1.0" encoding="UTF-8"?>
<testng-results skipped="0" failed="1" ignored="0" total="2" passed="1">
  <reporter-output>
  </reporter-output>
  <suite name="Default suite" duration-ms="125" started-at="2019-03-30T07:36:18Z" finished-at="2019-03-30T07:36:19Z">
    <groups>
    </groups>
    <test name="Default test" duration-ms="125" started-at="2019-03-30T07:36:18Z" finished-at="2019-03-30T07:36:19Z">
      <class name="TestNG.ExceptionTimeOutTest">
        <test-method status="FAIL" signature="infiniteLoop()[pri:0, instance:TestNG.ExceptionTimeOutTest@d8062c]" name="infiniteLoop" duration-ms="43" started-at="2019-03-30T07:36:18Z" finished-at="2019-03-30T07:36:18Z">
          <exception class="org.testng.internal.thread.ThreadTimeoutException">
            <message>
              <![CDATA[Method TestNG.ExceptionTimeOutTest.infiniteLoop() didn't finish within the time-out 2]]>
            </message>
            <full-stacktrace>
              <![CDATA[org.testng.internal.thread.ThreadTimeoutException: Method TestNG.ExceptionTimeOutTest.infiniteLoop() didn't finish within the time-out 2
at java.nio.ByteBuffer.arrayOffset(Unknown Source)
at sun.nio.cs.StreamEncoder.writeBytes(Unknown Source)
at sun.nio.cs.StreamEncoder.implFlushBuffer(Unknown Source)
at sun.nio.cs.StreamEncoder.flushBuffer(Unknown Source)
at java.io.OutputStreamWriter.flushBuffer(Unknown Source)
at java.io.PrintStream.newLine(Unknown Source)
at java.io.PrintStream.println(Unknown Source)
at TestNG.ExceptionTimeOutTest.infiniteLoop(ExceptionTimeOutTest.java:11)
at sun.reflect.NativeMethodAccessorImpl.invoke0(Native Method)
at sun.reflect.NativeMethodAccessorImpl.invoke(Unknown Source)
at sun.reflect.DelegatingMethodAccessorImpl.invoke(Unknown Source)
at java.lang.reflect.Method.invoke(Unknown Source)
at org.testng.internal.MethodInvocationHelper.invokeMethod(MethodInvocationHelper.java:124)
at org.testng.internal.InvokeMethodRunnable.runOne(InvokeMethodRunnable.java:54)
at org.testng.internal.InvokeMethodRunnable.run(InvokeMethodRunnable.java:40)
at java.util.concurrent.Executors$RunnableAdapter.call(Unknown Source)
at java.util.concurrent.FutureTask.run(Unknown Source)
at java.util.concurrent.ThreadPoolExecutor.runWorker(Unknown Source)
at java.util.concurrent.ThreadPoolExecutor$Worker.run(Unknown Source)
at java.lang.Thread.run(Unknown Source)
]]>
            </full-stacktrace>
          </exception> <!-- org.testng.internal.thread.ThreadTimeoutException -->
          <reporter-output>
          </reporter-output>
        </test-method> <!-- infiniteLoop -->
        <test-method status="PASS" signature="test1()[pri:0, instance:TestNG.ExceptionTimeOutTest@d8062c]" name="test1" duration-ms="3" started-at="2019-03-30T07:36:19Z" finished-at="2019-03-30T07:36:19Z">
          <exception class="java.lang.NumberFormatException">
            <message>
              <![CDATA[For input string: "100A"]]>
            </message>
            <full-stacktrace>
              <![CDATA[java.lang.NumberFormatException: For input string: "100A"
at java.lang.NumberFormatException.forInputString(Unknown Source)
at java.lang.Integer.parseInt(Unknown Source)
at java.lang.Integer.parseInt(Unknown Source)
at TestNG.ExceptionTimeOutTest.test1(ExceptionTimeOutTest.java:18)
at sun.reflect.NativeMethodAccessorImpl.invoke0(Native Method)
at sun.reflect.NativeMethodAccessorImpl.invoke(Unknown Source)
at sun.reflect.DelegatingMethodAccessorImpl.invoke(Unknown Source)
at java.lang.reflect.Method.invoke(Unknown Source)
at org.testng.internal.MethodInvocationHelper.invokeMethod(MethodInvocationHelper.java:124)
at org.testng.internal.Invoker.invokeMethod(Invoker.java:583)
at org.testng.internal.Invoker.invokeTestMethod(Invoker.java:719)
at org.testng.internal.Invoker.invokeTestMethods(Invoker.java:989)
at org.testng.internal.TestMethodWorker.invokeTestMethods(TestMethodWorker.java:125)
at org.testng.internal.TestMethodWorker.run(TestMethodWorker.java:109)
at org.testng.TestRunner.privateRun(TestRunner.java:648)
at org.testng.TestRunner.run(TestRunner.java:505)
at org.testng.SuiteRunner.runTest(SuiteRunner.java:455)
at org.testng.SuiteRunner.runSequentially(SuiteRunner.java:450)
at org.testng.SuiteRunner.privateRun(SuiteRunner.java:415)
at org.testng.SuiteRunner.run(SuiteRunner.java:364)
at org.testng.SuiteRunnerWorker.runSuite(SuiteRunnerWorker.java:52)
at org.testng.SuiteRunnerWorker.run(SuiteRunnerWorker.java:84)
at org.testng.TestNG.runSuitesSequentially(TestNG.java:1208)
at org.testng.TestNG.runSuitesLocally(TestNG.java:1137)
at org.testng.TestNG.runSuites(TestNG.java:1049)
at org.testng.TestNG.run(TestNG.java:1017)
at org.testng.remote.AbstractRemoteTestNG.run(AbstractRemoteTestNG.java:115)
at org.testng.remote.RemoteTestNG.initAndRun(RemoteTestNG.java:251)
at org.testng.remote.RemoteTestNG.main(RemoteTestNG.java:77)
]]>
            </full-stacktrace>
          </exception> <!-- java.lang.NumberFormatException -->
          <reporter-output>
          </reporter-output>
        </test-method> <!-- test1 -->
      </class> <!-- TestNG.ExceptionTimeOutTest -->
    </test> <!-- Default test -->
  </suite> <!-- Default suite -->
</testng-results>
